Workbook

Sheet Cover
B2: Helix Support Partners
B3: FY2026 operating plan & monthly P&L forecast (Jan-Dec 2026) - Business Finance case study
B4: Currency: mln IRT (Toman) unless stated; unit economics in IRT. Prepared by: Nima
B6: MODEL MAP
B7: Dashboard | C7: Headline KPIs and charts
B8: Assumptions | C8: Every driver, Given vs Assumed, with rationale (task: "state every ratio you assume")
B9: Topline_ExC | C9: Exhibit C completed: calls handled, rate card, other fees, revenue (task 1 input)
B10: Capacity_ExD | C10: Exhibit D: volume -> workload hours -> productive hours/FTE -> agent FTE -> hiring flow -> support roles -> seats (tasks 1-2)
B11: Erlang_Check | C11: Erlang C validation of the 78% voice occupancy against the 80/20 service level
B12: Costs | C12: Full cost stack: people, recruitment & attrition, technology & telephony, facilities, management, corporate overhead (task 3)
B13: PnL_ExE | C13: Exhibit E: monthly P&L revenue -> net profit with GM, EBITDA, EBITDA margin per month and FY (task 4)
B14: UnitEcon | C14: Revenue, cost and contribution per call vs per ticket; which line is more profitable and why (task 5)
B15: CostProgram_ExF | C15: Exhibit F: 8 cost initiatives ranked by net 12-month EBITDA impact; 90-day flags
B16: ZBB_Register | C16: Zero-based justification of every cost line: driver, minimum level, decision, owner
B17: Sensitivity | C17: One-at-a-time flex of key drivers (tornado data)
B19: CONVENTIONS
B20: Blue text | C20: Hard-coded input
B21: Black text | C21: Formula
B22: Green text | C22: Link to another sheet
B23: Yellow fill | C23: Key assumption / most sensitive input
B24: Costs in P&L | C24: Shown as negatives; FY column = sum (ratios recomputed on FY totals)
B26: NOTES ON THE CASE
B27: Exhibit labels | C27: Task text refers to "topline in Exhibit A" and "P&L structure in Exhibit D"; the case pages label these Exhibit C and E. Model follows the page labels.
B28: Rate card | C28: Blank in Exhibit C - assumed 32,000 IRT/call and 17,000 IRT/ticket (same ~425 IRT per handle-second). Flex in Assumptions row p_c / p_t.
B29: Currency | C29: Exhibit B quotes salaries in mln IRT; the "$60 allowance" note is treated as already embedded in the 50 mln IRT blended salary.
B30: Staffing risk | C30: Lever vol_real (Assumptions F) flexes billable volume while staffing stays on plan.

Sheet Dashboard
A1: Helix Support Partners - FY26 operating plan: dashboard
A2: All figures link to the model (mln IRT unless stated).
B4: FY26 KPI | C4: Value
B5: Revenue | C5: =PnL_ExE!$O$9 -> 204064.08
B6: Gross profit | C6: =PnL_ExE!$O$19 -> 81882.654
B7: Gross margin | C7: =PnL_ExE!$O$20 -> 0.40125952
B8: EBITDA | C8: =PnL_ExE!$O$35 -> 26561.855
B9: EBITDA margin | C9: =PnL_ExE!$O$36 -> 0.13016428
B10: Net profit | C10: =PnL_ExE!$O$42 -> 17785.447
B11: Net margin | C11: =PnL_ExE!$O$43 -> 0.087156184
B12: Avg agent HC | C12: =PnL_ExE!$O$49 -> 109.57883
B13: Avg total HC | C13: =PnL_ExE!$O$50 -> 135.16216
B14: Calls handled | C14: =PnL_ExE!$O$46 -> 4653400
B15: Tickets handled | C15: =PnL_ExE!$O$47 -> 3210000
B16: EBITDA per call (IRT) | C16: =UnitEcon!$O$23 -> 2996.2117
B17: EBITDA per ticket (IRT) | C17: =UnitEcon!$O$38 -> 3748.9106
B18: Voice EBITDA margin | C18: =UnitEcon!$O$24 -> 0.093631615
B19: Ticket EBITDA margin | C19: =UnitEcon!$O$39 -> 0.22052415
B20: Cost program - net 12m EBITDA | C20: =CostProgram_ExF!$M$16 -> 14409.52
B25: Chart data
B26: Month | C26: Jan-26 | D26: Feb-26 | E26: Mar-26 | F26: Apr-26 | G26: May-26 | H26: Jun-26 | I26: Jul-26 | J26: Aug-26 | K26: Sep-26 | L26: Oct-26 | M26: Nov-26 | N26: Dec-26
B27: Revenue | C27: =PnL_ExE!C9 -> 13502.8 | D27: =PnL_ExE!D9 -> 14803.312 | E27: =PnL_ExE!E9 -> 11840.8 | F27: =PnL_ExE!F9 -> 12808 | G27: =PnL_ExE!G9 -> 13605.2 | H27: =PnL_ExE!H9 -> 15029.6 | I27: =PnL_ExE!I9 -> 16794 | J27: =PnL_ExE!J9 -> 17591.2 | ... N27: =PnL_ExE!N9 -> 22140
B28: EBITDA | C28: =PnL_ExE!C35 -> 3226.1711 | D28: =PnL_ExE!D35 -> 3187.1184 | E28: =PnL_ExE!E35 -> 1101.7066 | F28: =PnL_ExE!F35 -> 81.838129 | G28: =PnL_ExE!G35 -> 830.85007 | H28: =PnL_ExE!H35 -> 950.75603 | I28: =PnL_ExE!I35 -> 1440.1246 | J28: =PnL_ExE!J35 -> 2028.5719 | ... N28: =PnL_ExE!N35 -> 3807.0277
B29: EBITDA margin | C29: =PnL_ExE!C36 -> 0.23892608 | D29: =PnL_ExE!D36 -> 0.21529765 | E29: =PnL_ExE!E36 -> 0.093043258 | F29: =PnL_ExE!F36 -> 0.0063896103 | G29: =PnL_ExE!G36 -> 0.061068567 | H29: =PnL_ExE!H36 -> 0.063258904 | I29: =PnL_ExE!I36 -> 0.085752325 | J29: =PnL_ExE!J36 -> 0.11531742 | ... N29: =PnL_ExE!N36 -> 0.17195247
B30: Agent HC | C30: =PnL_ExE!C49 -> 85.687461 | D30: =PnL_ExE!D49 -> 95.033824 | E30: =PnL_ExE!E49 -> 91.232471 | F30: =PnL_ExE!F49 -> 87.583172 | G30: =PnL_ExE!G49 -> 86.360399 | H30: =PnL_ExE!H49 -> 95.575913 | I30: =PnL_ExE!I49 -> 106.73547 | J30: =PnL_ExE!J49 -> 111.82924 | ... N30: =PnL_ExE!N49 -> 141.98098
B31: Agent FTE required | C31: =PnL_ExE!C48 -> 85.687461 | D31: =PnL_ExE!D48 -> 95.033824 | E31: =PnL_ExE!E48 -> 75.200841 | F31: =PnL_ExE!F48 -> 81.266631 | G31: =PnL_ExE!G48 -> 86.360399 | H31: =PnL_ExE!H48 -> 95.575913 | I31: =PnL_ExE!I48 -> 106.73547 | J31: =PnL_ExE!J48 -> 111.82924 | ... N31: =PnL_ExE!N48 -> 139.98049

Sheet Assumptions
A1: Assumptions register
A2: Every driver in one place. Blue = hard-coded input; yellow fill = key assumption (most sensitive). Source column states Given (case) vs Assumed (mine).
A4: ID | B4: Parameter | C4: Value | D4: Unit | E4: Source | F4: Rationale
A5: A. OPERATING DRIVERS - GIVEN (Exhibit A, 2025 actuals)
A6: aht_c | B6: Average handling time - call | C6: 75 | D6: seconds | E6: Given | F6: Talk + hold + after-call work per answered call
A7: aht_t | B7: Average handling time - ticket | C7: 40 | D7: seconds | E7: Given | F7: Per ticket resolved incl. re-reads and internal notes
A8: sl_tgt | B8: Service level target - voice (% answered) | C8: 0.8 | D8: % | E8: Given | F8: 80% answered within threshold below; used in Erlang C cross-check
A9: sl_sec | B9: Service level threshold - voice | C9: 20 | D9: seconds | E9: Given | F9: 80/20 contractual; breach triggers service credits
A10: occ_c | B10: Occupancy - voice | C10: 0.78 | D10: % | E10: Given | F10: Measured 2025 actual; embeds real-time queueing (Erlang) slack. Validated in Erlang sheet
A11: shr | B11: Shrinkage | C11: 0.3 | D11: % | E11: Given | F11: Paid but unavailable: breaks, leave, sickness, training, coaching, meetings
A12: paid | B12: Paid hours per agent per month | C12: 176 | D12: hours | E12: Given | F12: 22 working days x 8 hours
A13: sp_tl | B13: Span of control - team leader | C13: 15 | D13: agents / TL | E13: Given
A14: sp_om | B14: Span of control - operations manager | C14: 6 | D14: TLs / OM | E14: Given
A15: sp_qa | B15: Quality analysts | C15: 40 | D15: agents / QA | E15: Given | F15: Manual scoring, 2% sample
A16: n_sd | B16: Site director | C16: 1 | D16: FTE | E16: Given | F16: Fixed
A17: n_fh | B17: Finance / HR business partner | C17: 1 | D17: FTE | E17: Given | F17: Fixed
A18: tax | B18: Corporate tax rate | C18: 0.22 | D18: % | E18: Given | F18: Applied to profit before tax; monthly accrual, FY = sum
A19: B. OPERATING DRIVERS - ASSUMED (not in case; stated per instructions)
A20: occ_t | B20: Occupancy - tickets | C20: 0.9 | D20: % | E20: Assumed | F20: Tickets are asynchronous (95% < 4h): worked from a backlog, so no Erlang queueing slack; 10% kept for system latency / fatigue
A21: ot | B21: Share of productive hours covered by overtime | C21: 0.03 | D21: % | E21: Given (Ex. B) | F21: OT hours = 3% x workload hours; agent FTE sized on remaining 97%
A22: attr | B22: Agent attrition (monthly) | C22: 0.04 | D22: % of HC / month | E22: Assumed | F22: ~40% annualised - typical for high-volume contact centres
A23: nh_tr | B23: New-hire training (paid, non-productive) | C23: 0.5 | D23: months / hire | E23: Assumed | F23: 2 weeks classroom + nesting before an agent counts as productive capacity
A24: sp_wfm | B24: Workforce management analysts | C24: 75 | D24: agents / WFM | E24: Assumed | F24: Forecasting, scheduling, real-time adherence (industry 1:50-1:100)
A25: sp_trn | B25: Trainers | C25: 60 | D25: agents / trainer | E25: Assumed | F25: New-hire + refresher training; driven by 40% attrition
A26: sp_it | B26: IT / MIS support | C26: 75 | D26: agents / IT FTE | E26: Assumed | F26: Desktop, telephony and reporting support
A27: sp_hr | B27: HR, recruitment & admin | C27: 75 | D27: agents / FTE | E27: Assumed | F27: High hiring load (attrition + growth)
A28: n_am | B28: Client / account managers | C28: 2 | D28: FTE | E28: Assumed | F28: Fixed; own client QBRs, volume re-baselining and SLA reporting
A29: seat_r | B29: Agents per seat | C29: 1.5 | D29: agents / seat | E29: Assumed | F29: 16h x 7d operation - two shifts share a workstation; support staff 1 seat each
A30: seat_b | B30: Seat buffer on lease | C30: 0.1 | D30: % | E30: Assumed | F30: Lease sized to FY peak seats + buffer, signed for the full year (fixed cost)
A31: op_h | B31: Voice operating hours per day | C31: 16 | D31: hours | E31: Assumed | F31: 08:00-24:00, 7 days; used in Erlang C cross-check
A32: sched | B32: Schedule inefficiency allowance | C32: 0.05 | D32: % | E32: Assumed | F32: Shift granularity: rostered hours exceed pure Erlang need
A33: C. COST DRIVERS - GIVEN (Exhibit B) - gross monthly salary, mln IRT
A34: s_ag | B34: Agent - gross monthly salary | C34: 50 | D34: mln IRT / month | E34: Given | F34: Blended across shifts incl. shift & performance allowance
A35: s_tl | B35: Team leader | C35: 100 | D35: mln IRT / month | E35: Given
A36: s_qa | B36: Quality analyst | C36: 40 | D36: mln IRT / month | E36: Given
A37: s_om | B37: Operations manager | C37: 150 | D37: mln IRT / month | E37: Given
A38: s_sd | B38: Site director | C38: 200 | D38: mln IRT / month | E38: Given
A39: s_fh | B39: Finance / HR business partner | C39: 150 | D39: mln IRT / month | E39: Given
A40: oncost | B40: Employer on-costs | C40: 0.22 | D40: % of gross | E40: Given | F40: Social security, insurance, statutory benefits - all roles incl. overtime pay
A41: infl | B41: Annual wage inflation | C41: 0.25 | D41: % | E41: Given | F41: Effective 1 April 2026 - all salary lines and overtime rate
...

Sheet Topline_ExC
A1: Exhibit C - 2026 Topline (volumes, rate card, revenue)
A2: Calls offered, abandonment and tickets per Exhibit C. Rate card and other fees are my assumptions (blank in case). Units as stated per row.
A4: Line item | B4: Unit | C4: Jan-26 | D4: Feb-26 | E4: Mar-26 | F4: Apr-26 | G4: May-26 | H4: Jun-26 | I4: Jul-26 | J4: Aug-26 | K4: Sep-26 | L4: Oct-26 | M4: Nov-26 | N4: Dec-26 | O4: FY26 | P4: Basis / note
A5: TIMING & INDICES
A6: Month # | B6: # | C6: 1 | D6: 2 | E6: 3 | F6: 4 | G6: 5 | H6: 6 | I6: 7 | J6: 8 | K6: 9 | L6: 10 | M6: 11 | N6: 12
A7: Calendar days | B7: days | C7: 31 | D7: 28 | E7: 31 | F7: 30 | G7: 31 | H7: 30 | I7: 31 | J7: 31 | K7: 30 | L7: 31 | M7: 30 | N7: 31 | O7: =SUM(C7:N7) -> 365
A8: Wage index (1 Apr +25%) | B8: index | C8: =IF(C6>=Assumptions!$C$42,1+Assumptions!$C$41,1) -> 1 | D8: =IF(D6>=Assumptions!$C$42,1+Assumptions!$C$41,1) -> 1 | E8: =IF(E6>=Assumptions!$C$42,1+Assumptions!$C$41,1) -> 1 | F8: =IF(F6>=Assumptions!$C$42,1+Assumptions!$C$41,1) -> 1.25 | G8: =IF(G6>=Assumptions!$C$42,1+Assumptions!$C$41,1) -> 1.25 | H8: =IF(H6>=Assumptions!$C$42,1+Assumptions!$C$41,1) -> 1.25 | I8: =IF(I6>=Assumptions!$C$42,1+Assumptions!$C$41,1) -> 1.25 | J8: =IF(J6>=Assumptions!$C$42,1+Assumptions!$C$41,1) -> 1.25 | ... N8: =IF(N6>=Assumptions!$C$42,1+Assumptions!$C$41,1) -> 1.25 | O8: =AVERAGE(C8:N8) -> 1.1875
A9: Non-payroll cost index | B9: index | C9: =IF(C6>=Assumptions!$C$42,1+Assumptions!$C$58,1) -> 1 | D9: =IF(D6>=Assumptions!$C$42,1+Assumptions!$C$58,1) -> 1 | E9: =IF(E6>=Assumptions!$C$42,1+Assumptions!$C$58,1) -> 1 | F9: =IF(F6>=Assumptions!$C$42,1+Assumptions!$C$58,1) -> 1.15 | G9: =IF(G6>=Assumptions!$C$42,1+Assumptions!$C$58,1) -> 1.15 | H9: =IF(H6>=Assumptions!$C$42,1+Assumptions!$C$58,1) -> 1.15 | I9: =IF(I6>=Assumptions!$C$42,1+Assumptions!$C$58,1) -> 1.15 | J9: =IF(J6>=Assumptions!$C$42,1+Assumptions!$C$58,1) -> 1.15 | ... N9: =IF(N6>=Assumptions!$C$42,1+Assumptions!$C$58,1) -> 1.15 | O9: =AVERAGE(C9:N9) -> 1.1125
A10: VOLUME
A11: Inbound calls offered | B11: # | C11: 320000 | D11: 360000 | E11: 280000 | F11: 300000 | G11: 320000 | H11: 360000 | I11: 400000 | J11: 420000 | K11: 480000 | L11: 490000 | M11: 540000 | N11: 500000 | O11: =SUM(C11:N11) -> 4770000 | P11: Exhibit C (agreed with clients)
A12: Call abandonment rate | B12: % | C12: 0.03 | D12: 0.04 | E12: 0.02 | F12: 0.02 | G12: 0.02 | H12: 0.02 | I12: 0.02 | J12: 0.02 | K12: 0.02 | L12: 0.02 | M12: 0.04 | N12: 0.02 | O12: =1-O13/O11 -> 0.024444444 | P12: Exhibit C
A13: Calls handled - staffing plan | B13: # | C13: =C11*(1-C12) -> 310400 | D13: =D11*(1-D12) -> 345600 | E13: =E11*(1-E12) -> 274400 | F13: =F11*(1-F12) -> 294000 | G13: =G11*(1-G12) -> 313600 | H13: =H11*(1-H12) -> 352800 | I13: =I11*(1-I12) -> 392000 | J13: =J11*(1-J12) -> 411600 | ... N13: =N11*(1-N12) -> 490000 | O13: =SUM(C13:N13) -> 4653400 | P13: Offered x (1 - abandonment). Drives workload / FTE
A14: Tickets handled - staffing plan | B14: # | C14: 210000 | D14: 230000 | E14: 180000 | F14: 200000 | G14: 210000 | H14: 220000 | I14: 250000 | J14: 260000 | K14: 320000 | L14: 350000 | M14: 400000 | N14: 380000 | O14: =SUM(C14:N14) -> 3210000 | P14: Exhibit C
A15: Realised volume vs. plan (scenario lever) | B15: x | C15: =Assumptions!$C$70 -> 1 | D15: =Assumptions!$C$70 -> 1 | E15: =Assumptions!$C$70 -> 1 | F15: =Assumptions!$C$70 -> 1 | G15: =Assumptions!$C$70 -> 1 | H15: =Assumptions!$C$70 -> 1 | I15: =Assumptions!$C$70 -> 1 | J15: =Assumptions!$C$70 -> 1 | ... N15: =Assumptions!$C$70 -> 1 | O15: =AVERAGE(C15:N15) -> 1 | P15: 1.00 in base case
A16: Calls handled / billable | B16: # | C16: =C13*C15 -> 310400 | D16: =D13*D15 -> 345600 | E16: =E13*E15 -> 274400 | F16: =F13*F15 -> 294000 | G16: =G13*G15 -> 313600 | H16: =H13*H15 -> 352800 | I16: =I13*I15 -> 392000 | J16: =J13*J15 -> 411600 | ... N16: =N13*N15 -> 490000 | O16: =SUM(C16:N16) -> 4653400 | P16: Billing per call answered
A17: Tickets handled / billable | B17: # | C17: =C14*C15 -> 210000 | D17: =D14*D15 -> 230000 | E17: =E14*E15 -> 180000 | F17: =F14*F15 -> 200000 | G17: =G14*G15 -> 210000 | H17: =H14*H15 -> 220000 | I17: =I14*I15 -> 250000 | J17: =J14*J15 -> 260000 | ... N17: =N14*N15 -> 380000 | O17: =SUM(C17:N17) -> 3210000
A18: Total billable contacts | B18: # | C18: =C16+C17 -> 520400 | D18: =D16+D17 -> 575600 | E18: =E16+E17 -> 454400 | F18: =F16+F17 -> 494000 | G18: =G16+G17 -> 523600 | H18: =H16+H17 -> 572800 | I18: =I16+I17 -> 642000 | J18: =J16+J17 -> 671600 | ... N18: =N16+N17 -> 870000 | O18: =SUM(C18:N18) -> 7863400
A19: Voice share of contacts | B19: % | C19: =C16/C18 -> 0.59646426 | D19: =D16/D18 -> 0.60041696 | E19: =E16/E18 -> 0.60387324 | F19: =F16/F18 -> 0.5951417 | G19: =G16/G18 -> 0.59893048 | H19: =H16/H18 -> 0.61592179 | I19: =I16/I18 -> 0.6105919 | J19: =J16/J18 -> 0.6128648 | ... O19: =O16/O18 -> 0.59177964
A20: RATE CARD (fixed for 2026)
A21: Price per handled call | B21: IRT | C21: =Assumptions!$C$65 -> 32000 | D21: =Assumptions!$C$65 -> 32000 | E21: =Assumptions!$C$65 -> 32000 | F21: =Assumptions!$C$65 -> 32000 | G21: =Assumptions!$C$65 -> 32000 | H21: =Assumptions!$C$65 -> 32000 | I21: =Assumptions!$C$65 -> 32000 | J21: =Assumptions!$C$65 -> 32000 | ... N21: =Assumptions!$C$65 -> 32000 | O21: =IFERROR(O27*1000000/O16,0) -> 32000 | P21: Assumption E - see Assumptions
A22: Price per handled ticket | B22: IRT | C22: =Assumptions!$C$66 -> 17000 | D22: =Assumptions!$C$66 -> 17000 | E22: =Assumptions!$C$66 -> 17000 | F22: =Assumptions!$C$66 -> 17000 | G22: =Assumptions!$C$66 -> 17000 | H22: =Assumptions!$C$66 -> 17000 | I22: =Assumptions!$C$66 -> 17000 | J22: =Assumptions!$C$66 -> 17000 | ... N22: =Assumptions!$C$66 -> 17000 | O22: =IFERROR(O28*1000000/O17,0) -> 17000
A23: One-off: onboarding / set-up fee | B23: mln IRT | C23: 0 | D23: 0 | E23: 0 | F23: 0 | G23: 0 | H23: 0 | I23: 0 | J23: 0 | K23: 1000 | L23: 0 | M23: 0 | N23: 0 | O23: =SUM(C23:N23) -> 1000 | P23: Assumed: fee agreed for the Sep ramp of a new ticket workstream (+23% tickets)
A24: Service credits (SLA provision) | B24: mln IRT | C24: =-IF(C12>Assumptions!$C$67,Assumptions!$C$68*C27,0) -> 0 | D24: =-IF(D12>Assumptions!$C$67,Assumptions!$C$68*D27,0) -> -165.888 | E24: =-IF(E12>Assumptions!$C$67,Assumptions!$C$68*E27,0) -> 0 | F24: =-IF(F12>Assumptions!$C$67,Assumptions!$C$68*F27,0) -> 0 | G24: =-IF(G12>Assumptions!$C$67,Assumptions!$C$68*G27,0) -> 0 | H24: =-IF(H12>Assumptions!$C$67,Assumptions!$C$68*H27,0) -> 0 | I24: =-IF(I12>Assumptions!$C$67,Assumptions!$C$68*I27,0) -> 0 | J24: =-IF(J12>Assumptions!$C$67,Assumptions!$C$68*J27,0) -> 0 | ... N24: =-IF(N12>Assumptions!$C$67,Assumptions!$C$68*N27,0) -> 0 | O24: =SUM(C24:N24) -> -414.72 | P24: Assumed: 1.5% of call revenue when abandonment > 3%
A25: Other / one-off fees (net) | B25: mln IRT | C25: =C23+C24 -> 0 | D25: =D23+D24 -> -165.888 | E25: =E23+E24 -> 0 | F25: =F23+F24 -> 0 | G25: =G23+G24 -> 0 | H25: =H23+H24 -> 0 | I25: =I23+I24 -> 0 | J25: =J23+J24 -> 0 | ... N25: =N23+N24 -> 0 | O25: =SUM(C25:N25) -> 585.28
A26: REVENUE (derived) - mln IRT
A27: Call revenue | B27: mln IRT | C27: =C16*C21/1000000 -> 9932.8 | D27: =D16*D21/1000000 -> 11059.2 | E27: =E16*E21/1000000 -> 8780.8 | F27: =F16*F21/1000000 -> 9408 | G27: =G16*G21/1000000 -> 10035.2 | H27: =H16*H21/1000000 -> 11289.6 | I27: =I16*I21/1000000 -> 12544 | J27: =J16*J21/1000000 -> 13171.2 | ... N27: =N16*N21/1000000 -> 15680 | O27: =SUM(C27:N27) -> 148908.8
A28: Ticket revenue | B28: mln IRT | C28: =C17*C22/1000000 -> 3570 | D28: =D17*D22/1000000 -> 3910 | E28: =E17*E22/1000000 -> 3060 | F28: =F17*F22/1000000 -> 3400 | G28: =G17*G22/1000000 -> 3570 | H28: =H17*H22/1000000 -> 3740 | I28: =I17*I22/1000000 -> 4250 | J28: =J17*J22/1000000 -> 4420 | ... N28: =N17*N22/1000000 -> 6460 | O28: =SUM(C28:N28) -> 54570
A29: Other / one-off fees (net) | B29: mln IRT | C29: =C25 -> 0 | D29: =D25 -> -165.888 | E29: =E25 -> 0 | F29: =F25 -> 0 | G29: =G25 -> 0 | H29: =H25 -> 0 | I29: =I25 -> 0 | J29: =J25 -> 0 | ... N29: =N25 -> 0 | O29: =SUM(C29:N29) -> 585.28
A30: Gross revenue | B30: mln IRT | C30: =SUM(C27:C29) -> 13502.8 | D30: =SUM(D27:D29) -> 14803.312 | E30: =SUM(E27:E29) -> 11840.8 | F30: =SUM(F27:F29) -> 12808 | G30: =SUM(G27:G29) -> 13605.2 | H30: =SUM(H27:H29) -> 15029.6 | I30: =SUM(I27:I29) -> 16794 | J30: =SUM(J27:J29) -> 17591.2 | ... N30: =SUM(N27:N29) -> 22140 | O30: =SUM(C30:N30) -> 204064.08
A31: Revenue growth MoM | B31: % | C31: =0 -> 0 | D31: =D30/C30-1 -> 0.096314246 | E31: =E30/D30-1 -> -0.20012495 | F31: =F30/E30-1 -> 0.08168367 | G31: =G30/F30-1 -> 0.062242349 | H31: =H30/G30-1 -> 0.10469526 | I31: =I30/H30-1 -> 0.11739501 | J31: =J30/I30-1 -> 0.047469334 | K31: =K30/J30-1 -> 0.22179271 | ... N31: =N30/M30-1 -> -0.043213889

Sheet Capacity_ExD
A1: Exhibit D - Capacity & FTE build
A2: Volume -> workload hours -> net productive hours per FTE -> agent FTE -> headcount flow -> support roles -> seats. No jump straight to headcount.
A4: Line item | B4: Unit | C4: Jan-26 | D4: Feb-26 | E4: Mar-26 | F4: Apr-26 | G4: May-26 | H4: Jun-26 | I4: Jul-26 | J4: Aug-26 | K4: Sep-26 | L4: Oct-26 | M4: Nov-26 | N4: Dec-26 | O4: FY26 | P4: Basis / note
A5: 1. WORKLOAD - volume x AHT = productive hours required
A6: Calls handled (plan) | B6: # | C6: =Topline_ExC!C13 -> 310400 | D6: =Topline_ExC!D13 -> 345600 | E6: =Topline_ExC!E13 -> 274400 | F6: =Topline_ExC!F13 -> 294000 | G6: =Topline_ExC!G13 -> 313600 | H6: =Topline_ExC!H13 -> 352800 | I6: =Topline_ExC!I13 -> 392000 | J6: =Topline_ExC!J13 -> 411600 | ... N6: =Topline_ExC!N13 -> 490000 | O6: =SUM(C6:N6) -> 4653400
A7: AHT - call | B7: sec | C7: =Assumptions!$C$6 -> 75 | D7: =Assumptions!$C$6 -> 75 | E7: =Assumptions!$C$6 -> 75 | F7: =Assumptions!$C$6 -> 75 | G7: =Assumptions!$C$6 -> 75 | H7: =Assumptions!$C$6 -> 75 | I7: =Assumptions!$C$6 -> 75 | J7: =Assumptions!$C$6 -> 75 | ... N7: =Assumptions!$C$6 -> 75 | O7: =AVERAGE(C7:N7) -> 75
A8: Voice workload | B8: hours | C8: =C6*C7/3600 -> 6466.6667 | D8: =D6*D7/3600 -> 7200 | E8: =E6*E7/3600 -> 5716.6667 | F8: =F6*F7/3600 -> 6125 | G8: =G6*G7/3600 -> 6533.3333 | H8: =H6*H7/3600 -> 7350 | I8: =I6*I7/3600 -> 8166.6667 | J8: =J6*J7/3600 -> 8575 | ... N8: =N6*N7/3600 -> 10208.333 | O8: =SUM(C8:N8) -> 96945.833
A9: Tickets handled (plan) | B9: # | C9: =Topline_ExC!C14 -> 210000 | D9: =Topline_ExC!D14 -> 230000 | E9: =Topline_ExC!E14 -> 180000 | F9: =Topline_ExC!F14 -> 200000 | G9: =Topline_ExC!G14 -> 210000 | H9: =Topline_ExC!H14 -> 220000 | I9: =Topline_ExC!I14 -> 250000 | J9: =Topline_ExC!J14 -> 260000 | ... N9: =Topline_ExC!N14 -> 380000 | O9: =SUM(C9:N9) -> 3210000
A10: AHT - ticket | B10: sec | C10: =Assumptions!$C$7 -> 40 | D10: =Assumptions!$C$7 -> 40 | E10: =Assumptions!$C$7 -> 40 | F10: =Assumptions!$C$7 -> 40 | G10: =Assumptions!$C$7 -> 40 | H10: =Assumptions!$C$7 -> 40 | I10: =Assumptions!$C$7 -> 40 | J10: =Assumptions!$C$7 -> 40 | ... N10: =Assumptions!$C$7 -> 40 | O10: =AVERAGE(C10:N10) -> 40
A11: Ticket workload | B11: hours | C11: =C9*C10/3600 -> 2333.3333 | D11: =D9*D10/3600 -> 2555.5556 | E11: =E9*E10/3600 -> 2000 | F11: =F9*F10/3600 -> 2222.2222 | G11: =G9*G10/3600 -> 2333.3333 | H11: =H9*H10/3600 -> 2444.4444 | I11: =I9*I10/3600 -> 2777.7778 | J11: =J9*J10/3600 -> 2888.8889 | ... N11: =N9*N10/3600 -> 4222.2222 | O11: =SUM(C11:N11) -> 35666.667
A12: Total productive hours required | B12: hours | C12: =C8+C11 -> 8800 | D12: =D8+D11 -> 9755.5556 | E12: =E8+E11 -> 7716.6667 | F12: =F8+F11 -> 8347.2222 | G12: =G8+G11 -> 8866.6667 | H12: =H8+H11 -> 9794.4444 | I12: =I8+I11 -> 10944.444 | J12: =J8+J11 -> 11463.889 | ... N12: =N8+N11 -> 14430.556 | O12: =SUM(C12:N12) -> 132612.5
A13: 2. NET PRODUCTIVE HOURS PER AGENT FTE
A14: Paid hours per FTE | B14: hours | C14: =Assumptions!$C$12 -> 176 | D14: =Assumptions!$C$12 -> 176 | E14: =Assumptions!$C$12 -> 176 | F14: =Assumptions!$C$12 -> 176 | G14: =Assumptions!$C$12 -> 176 | H14: =Assumptions!$C$12 -> 176 | I14: =Assumptions!$C$12 -> 176 | J14: =Assumptions!$C$12 -> 176 | ... N14: =Assumptions!$C$12 -> 176 | O14: =AVERAGE(C14:N14) -> 176
A15: Shrinkage | B15: % | C15: =Assumptions!$C$11 -> 0.3 | D15: =Assumptions!$C$11 -> 0.3 | E15: =Assumptions!$C$11 -> 0.3 | F15: =Assumptions!$C$11 -> 0.3 | G15: =Assumptions!$C$11 -> 0.3 | H15: =Assumptions!$C$11 -> 0.3 | I15: =Assumptions!$C$11 -> 0.3 | J15: =Assumptions!$C$11 -> 0.3 | ... N15: =Assumptions!$C$11 -> 0.3 | O15: =AVERAGE(C15:N15) -> 0.3
A16: Available (logged-in) hours per FTE | B16: hours | C16: =C14*(1-C15) -> 123.2 | D16: =D14*(1-D15) -> 123.2 | E16: =E14*(1-E15) -> 123.2 | F16: =F14*(1-F15) -> 123.2 | G16: =G14*(1-G15) -> 123.2 | H16: =H14*(1-H15) -> 123.2 | I16: =I14*(1-I15) -> 123.2 | J16: =J14*(1-J15) -> 123.2 | ... N16: =N14*(1-N15) -> 123.2 | O16: =AVERAGE(C16:N16) -> 123.2
A17: Occupancy - voice | B17: % | C17: =Assumptions!$C$10 -> 0.78 | D17: =Assumptions!$C$10 -> 0.78 | E17: =Assumptions!$C$10 -> 0.78 | F17: =Assumptions!$C$10 -> 0.78 | G17: =Assumptions!$C$10 -> 0.78 | H17: =Assumptions!$C$10 -> 0.78 | I17: =Assumptions!$C$10 -> 0.78 | J17: =Assumptions!$C$10 -> 0.78 | ... N17: =Assumptions!$C$10 -> 0.78 | O17: =AVERAGE(C17:N17) -> 0.78
A18: Occupancy - tickets | B18: % | C18: =Assumptions!$C$20 -> 0.9 | D18: =Assumptions!$C$20 -> 0.9 | E18: =Assumptions!$C$20 -> 0.9 | F18: =Assumptions!$C$20 -> 0.9 | G18: =Assumptions!$C$20 -> 0.9 | H18: =Assumptions!$C$20 -> 0.9 | I18: =Assumptions!$C$20 -> 0.9 | J18: =Assumptions!$C$20 -> 0.9 | ... N18: =Assumptions!$C$20 -> 0.9 | O18: =AVERAGE(C18:N18) -> 0.9
A19: Net productive hours / FTE - voice | B19: hours | C19: =C16*C17 -> 96.096 | D19: =D16*D17 -> 96.096 | E19: =E16*E17 -> 96.096 | F19: =F16*F17 -> 96.096 | G19: =G16*G17 -> 96.096 | H19: =H16*H17 -> 96.096 | I19: =I16*I17 -> 96.096 | J19: =J16*J17 -> 96.096 | ... N19: =N16*N17 -> 96.096 | O19: =AVERAGE(C19:N19) -> 96.096 | P19: 176 x (1-30%) x 78% = 96.1h
A20: Net productive hours / FTE - tickets | B20: hours | C20: =C16*C18 -> 110.88 | D20: =D16*D18 -> 110.88 | E20: =E16*E18 -> 110.88 | F20: =F16*F18 -> 110.88 | G20: =G16*G18 -> 110.88 | H20: =H16*H18 -> 110.88 | I20: =I16*I18 -> 110.88 | J20: =J16*J18 -> 110.88 | ... N20: =N16*N18 -> 110.88 | O20: =AVERAGE(C20:N20) -> 110.88 | P20: 176 x (1-30%) x 90% = 110.9h
A21: Capacity per voice FTE | B21: calls / month | C21: =C19*3600/C7 -> 4612.608 | D21: =D19*3600/D7 -> 4612.608 | E21: =E19*3600/E7 -> 4612.608 | F21: =F19*3600/F7 -> 4612.608 | G21: =G19*3600/G7 -> 4612.608 | H21: =H19*3600/H7 -> 4612.608 | I21: =I19*3600/I7 -> 4612.608 | J21: =J19*3600/J7 -> 4612.608 | ... N21: =N19*3600/N7 -> 4612.608 | O21: =AVERAGE(C21:N21) -> 4612.608
A22: Capacity per ticket FTE | B22: tickets / month | C22: =C20*3600/C10 -> 9979.2 | D22: =D20*3600/D10 -> 9979.2 | E22: =E20*3600/E10 -> 9979.2 | F22: =F20*3600/F10 -> 9979.2 | G22: =G20*3600/G10 -> 9979.2 | H22: =H20*3600/H10 -> 9979.2 | I22: =I20*3600/I10 -> 9979.2 | J22: =J20*3600/J10 -> 9979.2 | ... N22: =N20*3600/N10 -> 9979.2 | O22: =AVERAGE(C22:N22) -> 9979.2
A23: 3. OVERTIME COVER (3% of productive hours)
A24: OT share of productive hours | B24: % | C24: =Assumptions!$C$21 -> 0.03 | D24: =Assumptions!$C$21 -> 0.03 | E24: =Assumptions!$C$21 -> 0.03 | F24: =Assumptions!$C$21 -> 0.03 | G24: =Assumptions!$C$21 -> 0.03 | H24: =Assumptions!$C$21 -> 0.03 | I24: =Assumptions!$C$21 -> 0.03 | J24: =Assumptions!$C$21 -> 0.03 | ... N24: =Assumptions!$C$21 -> 0.03 | O24: =AVERAGE(C24:N24) -> 0.03
A25: Overtime hours | B25: hours | C25: =C12*C24 -> 264 | D25: =D12*D24 -> 292.66667 | E25: =E12*E24 -> 231.5 | F25: =F12*F24 -> 250.41667 | G25: =G12*G24 -> 266 | H25: =H12*H24 -> 293.83333 | I25: =I12*I24 -> 328.33333 | J25: =J12*J24 -> 343.91667 | ... N25: =N12*N24 -> 432.91667 | O25: =SUM(C25:N25) -> 3978.375 | P25: Assumed 1 OT hour = 1 productive hour
A26: Voice hours covered by rostered FTE | B26: hours | C26: =C8*(1-C24) -> 6272.6667 | D26: =D8*(1-D24) -> 6984 | E26: =E8*(1-E24) -> 5545.1667 | F26: =F8*(1-F24) -> 5941.25 | G26: =G8*(1-G24) -> 6337.3333 | H26: =H8*(1-H24) -> 7129.5 | I26: =I8*(1-I24) -> 7921.6667 | J26: =J8*(1-J24) -> 8317.75 | ... N26: =N8*(1-N24) -> 9902.0833 | O26: =SUM(C26:N26) -> 94037.458
A27: Ticket hours covered by rostered FTE | B27: hours | C27: =C11*(1-C24) -> 2263.3333 | D27: =D11*(1-D24) -> 2478.8889 | E27: =E11*(1-E24) -> 1940 | F27: =F11*(1-F24) -> 2155.5556 | G27: =G11*(1-G24) -> 2263.3333 | H27: =H11*(1-H24) -> 2371.1111 | I27: =I11*(1-I24) -> 2694.4444 | J27: =J11*(1-J24) -> 2802.2222 | ... N27: =N11*(1-N24) -> 4095.5556 | O27: =SUM(C27:N27) -> 34596.667
A28: 4. AGENT FTE REQUIREMENT
A29: Voice agent FTE required | B29: FTE | C29: =C26/C19 -> 65.275003 | D29: =D26/D19 -> 72.677323 | E29: =E26/E19 -> 57.704448 | F29: =F26/F19 -> 61.826195 | G29: =G26/G19 -> 65.947941 | H29: =H26/H19 -> 74.191434 | I29: =I26/I19 -> 82.434926 | J29: =J26/J19 -> 86.556672 | ... N29: =N26/N19 -> 103.04366 | O29: =AVERAGE(C29:N29) -> 81.54819
A30: Ticket agent FTE required | B30: FTE | C30: =C27/C20 -> 20.412458 | D30: =D27/D20 -> 22.356502 | E30: =E27/E20 -> 17.496392 | F30: =F27/F20 -> 19.440436 | G30: =G27/G20 -> 20.412458 | H30: =H27/H20 -> 21.38448 | I30: =I27/I20 -> 24.300545 | J30: =J27/J20 -> 25.272567 | ... N30: =N27/N20 -> 36.936829 | O30: =AVERAGE(C30:N30) -> 26.001583
A31: Total agent FTE required (productive) | B31: FTE | C31: =C29+C30 -> 85.687461 | D31: =D29+D30 -> 95.033824 | E31: =E29+E30 -> 75.200841 | F31: =F29+F30 -> 81.266631 | G31: =G29+G30 -> 86.360399 | H31: =H29+H30 -> 95.575913 | I31: =I29+I30 -> 106.73547 | J31: =J29+J30 -> 111.82924 | ... N31: =N29+N30 -> 139.98049 | O31: =AVERAGE(C31:N31) -> 107.54977
A32: 5. AGENT HEADCOUNT FLOW - no-layoff policy: surplus is released only through attrition
A33: Opening agent headcount | B33: FTE | C33: =C31 -> 85.687461 | D33: =C36 -> 85.687461 | E33: =D36 -> 95.033824 | F33: =E36 -> 91.232471 | G33: =F36 -> 87.583172 | H33: =G36 -> 86.360399 | I33: =H36 -> 95.575913 | J33: =I36 -> 106.73547 | K33: =J36 -> 111.82924 | ... N33: =M36 -> 147.89686 | O33: =C33 -> 85.687461 | P33: Dec-25 exit assumed = Jan-26 requirement
A34: Leavers (attrition) | B34: FTE | C34: =C33*Assumptions!$C$22 -> 3.4274984 | D34: =D33*Assumptions!$C$22 -> 3.4274984 | E34: =E33*Assumptions!$C$22 -> 3.801353 | F34: =F33*Assumptions!$C$22 -> 3.6492988 | G34: =G33*Assumptions!$C$22 -> 3.5033269 | H34: =H33*Assumptions!$C$22 -> 3.454416 | I34: =I33*Assumptions!$C$22 -> 3.8230365 | J34: =J33*Assumptions!$C$22 -> 4.2694189 | ... N34: =N33*Assumptions!$C$22 -> 5.9158742 | O34: =SUM(C34:N34) -> 50.346097
A35: New hires | B35: FTE | C35: =MAX(0,C31-(C33-C34)) -> 3.4274984 | D35: =MAX(0,D31-(D33-D34)) -> 12.773862 | E35: =MAX(0,E31-(E33-E34)) -> 0 | F35: =MAX(0,F31-(F33-F34)) -> 0 | G35: =MAX(0,G31-(G33-G34)) -> 2.2805534 | H35: =MAX(0,H31-(H33-H34)) -> 12.66993 | I35: =MAX(0,I31-(I33-I34)) -> 14.982595 | J35: =MAX(0,J31-(J33-J34)) -> 9.363187 | ... N35: =MAX(0,N31-(N33-N34)) -> 0 | O35: =SUM(C35:N35) -> 106.63962 | P35: Hire only the gap after attrition
A36: Closing agent headcount (on payroll) | B36: FTE | C36: =C33-C34+C35 -> 85.687461 | D36: =D33-D34+D35 -> 95.033824 | E36: =E33-E34+E35 -> 91.232471 | F36: =F33-F34+F35 -> 87.583172 | G36: =G33-G34+G35 -> 86.360399 | H36: =H33-H34+H35 -> 95.575913 | I36: =I33-I34+I35 -> 106.73547 | J36: =J33-J34+J35 -> 111.82924 | ... N36: =N33-N34+N35 -> 141.98098 | O36: =AVERAGE(C36:N36) -> 109.57883
A37: Surplus / idle agent FTE | B37: FTE | C37: =C36-C31 -> 0 | D37: =D36-D31 -> 0 | E37: =E36-E31 -> 16.03163 | F37: =F36-F31 -> 6.3165416 | G37: =G36-G31 -> 0 | H37: =H36-H31 -> 0 | I37: =I36-I31 -> 0 | J37: =J36-J31 -> 0 | ... N37: =N36-N31 -> 2.0004956 | O37: =AVERAGE(C37:N37) -> 2.0290556 | P37: Paid capacity above need (e.g. Mar after Feb peak)
A38: Trainee FTE (non-productive) | B38: FTE | C38: =C35*Assumptions!$C$23 -> 1.7137492 | D38: =D35*Assumptions!$C$23 -> 6.386931 | E38: =E35*Assumptions!$C$23 -> 0 | F38: =F35*Assumptions!$C$23 -> 0 | G38: =G35*Assumptions!$C$23 -> 1.1402767 | H38: =H35*Assumptions!$C$23 -> 6.3349652 | I38: =I35*Assumptions!$C$23 -> 7.4912973 | J38: =J35*Assumptions!$C$23 -> 4.6815935 | ... N38: =N35*Assumptions!$C$23 -> 0 | O38: =AVERAGE(C38:N38) -> 4.4433174
A39: Agent utilisation (required / on payroll) | B39: % | C39: =C31/C36 -> 1 | D39: =D31/D36 -> 1 | E39: =E31/E36 -> 0.82427714 | F39: =F31/F36 -> 0.92787951 | G39: =G31/G36 -> 1 | H39: =H31/H36 -> 1 | I39: =I31/I36 -> 1 | J39: =J31/J36 -> 1 | ... O39: =O31/O36 -> 0.98148314
A40: 6. SUPPORT & MANAGEMENT ROLES (rounded up to whole heads; ratchet - never reduced within the year)
A41: Team leaders (1:15 agents) | B41: HC | C41: =ROUNDUP(C36/Assumptions!$C$13,0) -> 6 | D41: =MAX(C41,ROUNDUP(D36/Assumptions!$C$13,0)) -> 7 | E41: =MAX(D41,ROUNDUP(E36/Assumptions!$C$13,0)) -> 7 | F41: =MAX(E41,ROUNDUP(F36/Assumptions!$C$13,0)) -> 7 | G41: =MAX(F41,ROUNDUP(G36/Assumptions!$C$13,0)) -> 7 | H41: =MAX(G41,ROUNDUP(H36/Assumptions!$C$13,0)) -> 7 | I41: =MAX(H41,ROUNDUP(I36/Assumptions!$C$13,0)) -> 8 | J41: =MAX(I41,ROUNDUP(J36/Assumptions!$C$13,0)) -> 8 | K41: =MAX(J41,ROUNDUP(K36/Assumptions!$C$13,0)) -> 9 | ... N41: =MAX(M41,ROUNDUP(N36/Assumptions!$C$13,0)) -> 10 | O41: =AVERAGE(C41:N41) -> 8 | P41: Ratchet: support roles are not cut within the year
...

Sheet Erlang_Check
A1: Erlang C cross-check - is 78% voice occupancy consistent with the 80/20 service level?
A2: Bottom-up interval staffing for one month. Select a month in C5. Grid columns J:AH test N = ceiling(A)+k agents; required N is the first that meets 80/20.
B5: Selected month | C5: Nov-26
B6: Calls handled in month | C6: =INDEX(Topline_ExC!$C$13:$N$13,MATCH($C$5,Topline_ExC!$C$4:$N$4,0)) -> 518400
B7: Calendar days | C7: =INDEX(Topline_ExC!$C$7:$N$7,MATCH($C$5,Topline_ExC!$C$4:$N$4,0)) -> 30
B8: Calls per day | C8: =C6/C7 -> 17280
B9: AHT (sec) | C9: =Assumptions!$C$6 -> 75
B10: SL target | C10: =Assumptions!$C$8 -> 0.8
B11: SL threshold (sec) | C11: =Assumptions!$C$9 -> 20
J13: k (N = ceiling(A) + k) -> cell = N if SL(N) >= target else 9999
B14: Hour | C14: % of daily calls | D14: Calls in hour | E14: Traffic A (Erlangs) | F14: Required agents N | G14: SL achieved | H14: Occupancy A/N | J14: 1 | K14: 2 | L14: 3 | M14: 4 | N14: 5 | O14: 6 | P14: 7 | Q14: 8 | R14: 9 | S14: 10 | T14: 11 | U14: 12 | V14: 13 | W14: 14 | X14: 15 | Y14: 16 | Z14: 17 | AA14: 18 | AB14: 19 | AC14: 20 | AD14: 21 | AE14: 22 | AF14: 23 | AG14: 24 | AH14: 25
B15: 08:00-09:00 | C15: 0.04 | D15: =$C$8*C15 -> 691.2 | E15: =D15*$C$9/3600 -> 14.4 | F15: =MIN(J15:AH15) -> 18 | G15: =1-POISSON(F15,E15,FALSE())/(POISSON(F15,E15,FALSE())+(1-E15/F15)*POISSON(F15-1,E15,TRUE()))*EXP(-(F15-E15)*$C$11/$C$9) -> 0.8931881 | H15: =E15/F15 -> 0.8 | J15: =IF(1-POISSON((ROUNDUP($E15,0)+J$14),$E15,FALSE())/(POISSON((ROUNDUP($E15,0)+J$14),$E15,FALSE())+(1-$E15/(ROUNDUP($E15,0)+J$14))*POISSON((ROUNDUP($E15,0)+J$14)-1,$E15,TRUE()))*EXP(-((ROUNDUP($E15,0)+J$14)-$E15)*$C$11/$C$9)>=$C$10,(ROUNDUP($E15,0)+J$14),9999) -> 9999 | K15: =IF(1-POISSON((ROUNDUP($E15,0)+K$14),$E15,FALSE())/(POISSON((ROUNDUP($E15,0)+K$14),$E15,FALSE())+(1-$E15/(ROUNDUP($E15,0)+K$14))*POISSON((ROUNDUP($E15,0)+K$14)-1,$E15,TRUE()))*EXP(-((ROUNDUP($E15,0)+K$14)-$E15)*$C$11/$C$9)>=$C$10,(ROUNDUP($E15,0)+K$14),9999) -> 9999 | L15: =IF(1-POISSON((ROUNDUP($E15,0)+L$14),$E15,FALSE())/(POISSON((ROUNDUP($E15,0)+L$14),$E15,FALSE())+(1-$E15/(ROUNDUP($E15,0)+L$14))*POISSON((ROUNDUP($E15,0)+L$14)-1,$E15,TRUE()))*EXP(-((ROUNDUP($E15,0)+L$14)-$E15)*$C$11/$C$9)>=$C$10,(ROUNDUP($E15,0)+L$14),9999) -> 18 | M15: =IF(1-POISSON((ROUNDUP($E15,0)+M$14),$E15,FALSE())/(POISSON((ROUNDUP($E15,0)+M$14),$E15,FALSE())+(1-$E15/(ROUNDUP($E15,0)+M$14))*POISSON((ROUNDUP($E15,0)+M$14)-1,$E15,TRUE()))*EXP(-((ROUNDUP($E15,0)+M$14)-$E15)*$C$11/$C$9)>=$C$10,(ROUNDUP($E15,0)+M$14),9999) -> 19 | N15: =IF(1-POISSON((ROUNDUP($E15,0)+N$14),$E15,FALSE())/(POISSON((ROUNDUP($E15,0)+N$14),$E15,FALSE())+(1-$E15/(ROUNDUP($E15,0)+N$14))*POISSON((ROUNDUP($E15,0)+N$14)-1,$E15,TRUE()))*EXP(-((ROUNDUP($E15,0)+N$14)-$E15)*$C$11/$C$9)>=$C$10,(ROUNDUP($E15,0)+N$14),9999) -> 20 | O15: =IF(1-POISSON((ROUNDUP($E15,0)+O$14),$E15,FALSE())/(POISSON((ROUNDUP($E15,0)+O$14),$E15,FALSE())+(1-$E15/(ROUNDUP($E15,0)+O$14))*POISSON((ROUNDUP($E15,0)+O$14)-1,$E15,TRUE()))*EXP(-((ROUNDUP($E15,0)+O$14)-$E15)*$C$11/$C$9)>=$C$10,(ROUNDUP($E15,0)+O$14),9999) -> 21 | P15: =IF(1-POISSON((ROUNDUP($E15,0)+P$14),$E15,FALSE())/(POISSON((ROUNDUP($E15,0)+P$14),$E15,FALSE())+(1-$E15/(ROUNDUP($E15,0)+P$14))*POISSON((ROUNDUP($E15,0)+P$14)-1,$E15,TRUE()))*EXP(-((ROUNDUP($E15,0)+P$14)-$E15)*$C$11/$C$9)>=$C$10,(ROUNDUP($E15,0)+P$14),9999) -> 22 | Q15: =IF(1-POISSON((ROUNDUP($E15,0)+Q$14),$E15,FALSE())/(POISSON((ROUNDUP($E15,0)+Q$14),$E15,FALSE())+(1-$E15/(ROUNDUP($E15,0)+Q$14))*POISSON((ROUNDUP($E15,0)+Q$14)-1,$E15,TRUE()))*EXP(-((ROUNDUP($E15,0)+Q$14)-$E15)*$C$11/$C$9)>=$C$10,(ROUNDUP($E15,0)+Q$14),9999) -> 23 | ... AH15: =IF(1-POISSON((ROUNDUP($E15,0)+AH$14),$E15,FALSE())/(POISSON((ROUNDUP($E15,0)+AH$14),$E15,FALSE())+(1-$E15/(ROUNDUP($E15,0)+AH$14))*POISSON((ROUNDUP($E15,0)+AH$14)-1,$E15,TRUE()))*EXP(-((ROUNDUP($E15,0)+AH$14)-$E15)*$C$11/$C$9)>=$C$10,(ROUNDUP($E15,0)+AH$14),9999) -> 40
B16: 09:00-10:00 | C16: 0.05 | D16: =$C$8*C16 -> 864 | E16: =D16*$C$9/3600 -> 18 | F16: =MIN(J16:AH16) -> 21 | G16: =1-POISSON(F16,E16,FALSE())/(POISSON(F16,E16,FALSE())+(1-E16/F16)*POISSON(F16-1,E16,TRUE()))*EXP(-(F16-E16)*$C$11/$C$9) -> 0.82212345 | H16: =E16/F16 -> 0.85714286 | J16: =IF(1-POISSON((ROUNDUP($E16,0)+J$14),$E16,FALSE())/(POISSON((ROUNDUP($E16,0)+J$14),$E16,FALSE())+(1-$E16/(ROUNDUP($E16,0)+J$14))*POISSON((ROUNDUP($E16,0)+J$14)-1,$E16,TRUE()))*EXP(-((ROUNDUP($E16,0)+J$14)-$E16)*$C$11/$C$9)>=$C$10,(ROUNDUP($E16,0)+J$14),9999) -> 9999 | K16: =IF(1-POISSON((ROUNDUP($E16,0)+K$14),$E16,FALSE())/(POISSON((ROUNDUP($E16,0)+K$14),$E16,FALSE())+(1-$E16/(ROUNDUP($E16,0)+K$14))*POISSON((ROUNDUP($E16,0)+K$14)-1,$E16,TRUE()))*EXP(-((ROUNDUP($E16,0)+K$14)-$E16)*$C$11/$C$9)>=$C$10,(ROUNDUP($E16,0)+K$14),9999) -> 9999 | L16: =IF(1-POISSON((ROUNDUP($E16,0)+L$14),$E16,FALSE())/(POISSON((ROUNDUP($E16,0)+L$14),$E16,FALSE())+(1-$E16/(ROUNDUP($E16,0)+L$14))*POISSON((ROUNDUP($E16,0)+L$14)-1,$E16,TRUE()))*EXP(-((ROUNDUP($E16,0)+L$14)-$E16)*$C$11/$C$9)>=$C$10,(ROUNDUP($E16,0)+L$14),9999) -> 21 | M16: =IF(1-POISSON((ROUNDUP($E16,0)+M$14),$E16,FALSE())/(POISSON((ROUNDUP($E16,0)+M$14),$E16,FALSE())+(1-$E16/(ROUNDUP($E16,0)+M$14))*POISSON((ROUNDUP($E16,0)+M$14)-1,$E16,TRUE()))*EXP(-((ROUNDUP($E16,0)+M$14)-$E16)*$C$11/$C$9)>=$C$10,(ROUNDUP($E16,0)+M$14),9999) -> 22 | N16: =IF(1-POISSON((ROUNDUP($E16,0)+N$14),$E16,FALSE())/(POISSON((ROUNDUP($E16,0)+N$14),$E16,FALSE())+(1-$E16/(ROUNDUP($E16,0)+N$14))*POISSON((ROUNDUP($E16,0)+N$14)-1,$E16,TRUE()))*EXP(-((ROUNDUP($E16,0)+N$14)-$E16)*$C$11/$C$9)>=$C$10,(ROUNDUP($E16,0)+N$14),9999) -> 23 | O16: =IF(1-POISSON((ROUNDUP($E16,0)+O$14),$E16,FALSE())/(POISSON((ROUNDUP($E16,0)+O$14),$E16,FALSE())+(1-$E16/(ROUNDUP($E16,0)+O$14))*POISSON((ROUNDUP($E16,0)+O$14)-1,$E16,TRUE()))*EXP(-((ROUNDUP($E16,0)+O$14)-$E16)*$C$11/$C$9)>=$C$10,(ROUNDUP($E16,0)+O$14),9999) -> 24 | P16: =IF(1-POISSON((ROUNDUP($E16,0)+P$14),$E16,FALSE())/(POISSON((ROUNDUP($E16,0)+P$14),$E16,FALSE())+(1-$E16/(ROUNDUP($E16,0)+P$14))*POISSON((ROUNDUP($E16,0)+P$14)-1,$E16,TRUE()))*EXP(-((ROUNDUP($E16,0)+P$14)-$E16)*$C$11/$C$9)>=$C$10,(ROUNDUP($E16,0)+P$14),9999) -> 25 | Q16: =IF(1-POISSON((ROUNDUP($E16,0)+Q$14),$E16,FALSE())/(POISSON((ROUNDUP($E16,0)+Q$14),$E16,FALSE())+(1-$E16/(ROUNDUP($E16,0)+Q$14))*POISSON((ROUNDUP($E16,0)+Q$14)-1,$E16,TRUE()))*EXP(-((ROUNDUP($E16,0)+Q$14)-$E16)*$C$11/$C$9)>=$C$10,(ROUNDUP($E16,0)+Q$14),9999) -> 26 | ... AH16: =IF(1-POISSON((ROUNDUP($E16,0)+AH$14),$E16,FALSE())/(POISSON((ROUNDUP($E16,0)+AH$14),$E16,FALSE())+(1-$E16/(ROUNDUP($E16,0)+AH$14))*POISSON((ROUNDUP($E16,0)+AH$14)-1,$E16,TRUE()))*EXP(-((ROUNDUP($E16,0)+AH$14)-$E16)*$C$11/$C$9)>=$C$10,(ROUNDUP($E16,0)+AH$14),9999) -> 43
B17: 10:00-11:00 | C17: 0.065 | D17: =$C$8*C17 -> 1123.2 | E17: =D17*$C$9/3600 -> 23.4 | F17: =MIN(J17:AH17) -> 27 | G17: =1-POISSON(F17,E17,FALSE())/(POISSON(F17,E17,FALSE())+(1-E17/F17)*POISSON(F17-1,E17,TRUE()))*EXP(-(F17-E17)*$C$11/$C$9) -> 0.85772559 | H17: =E17/F17 -> 0.86666667 | J17: =IF(1-POISSON((ROUNDUP($E17,0)+J$14),$E17,FALSE())/(POISSON((ROUNDUP($E17,0)+J$14),$E17,FALSE())+(1-$E17/(ROUNDUP($E17,0)+J$14))*POISSON((ROUNDUP($E17,0)+J$14)-1,$E17,TRUE()))*EXP(-((ROUNDUP($E17,0)+J$14)-$E17)*$C$11/$C$9)>=$C$10,(ROUNDUP($E17,0)+J$14),9999) -> 9999 | K17: =IF(1-POISSON((ROUNDUP($E17,0)+K$14),$E17,FALSE())/(POISSON((ROUNDUP($E17,0)+K$14),$E17,FALSE())+(1-$E17/(ROUNDUP($E17,0)+K$14))*POISSON((ROUNDUP($E17,0)+K$14)-1,$E17,TRUE()))*EXP(-((ROUNDUP($E17,0)+K$14)-$E17)*$C$11/$C$9)>=$C$10,(ROUNDUP($E17,0)+K$14),9999) -> 9999 | L17: =IF(1-POISSON((ROUNDUP($E17,0)+L$14),$E17,FALSE())/(POISSON((ROUNDUP($E17,0)+L$14),$E17,FALSE())+(1-$E17/(ROUNDUP($E17,0)+L$14))*POISSON((ROUNDUP($E17,0)+L$14)-1,$E17,TRUE()))*EXP(-((ROUNDUP($E17,0)+L$14)-$E17)*$C$11/$C$9)>=$C$10,(ROUNDUP($E17,0)+L$14),9999) -> 27 | M17: =IF(1-POISSON((ROUNDUP($E17,0)+M$14),$E17,FALSE())/(POISSON((ROUNDUP($E17,0)+M$14),$E17,FALSE())+(1-$E17/(ROUNDUP($E17,0)+M$14))*POISSON((ROUNDUP($E17,0)+M$14)-1,$E17,TRUE()))*EXP(-((ROUNDUP($E17,0)+M$14)-$E17)*$C$11/$C$9)>=$C$10,(ROUNDUP($E17,0)+M$14),9999) -> 28 | N17: =IF(1-POISSON((ROUNDUP($E17,0)+N$14),$E17,FALSE())/(POISSON((ROUNDUP($E17,0)+N$14),$E17,FALSE())+(1-$E17/(ROUNDUP($E17,0)+N$14))*POISSON((ROUNDUP($E17,0)+N$14)-1,$E17,TRUE()))*EXP(-((ROUNDUP($E17,0)+N$14)-$E17)*$C$11/$C$9)>=$C$10,(ROUNDUP($E17,0)+N$14),9999) -> 29 | O17: =IF(1-POISSON((ROUNDUP($E17,0)+O$14),$E17,FALSE())/(POISSON((ROUNDUP($E17,0)+O$14),$E17,FALSE())+(1-$E17/(ROUNDUP($E17,0)+O$14))*POISSON((ROUNDUP($E17,0)+O$14)-1,$E17,TRUE()))*EXP(-((ROUNDUP($E17,0)+O$14)-$E17)*$C$11/$C$9)>=$C$10,(ROUNDUP($E17,0)+O$14),9999) -> 30 | P17: =IF(1-POISSON((ROUNDUP($E17,0)+P$14),$E17,FALSE())/(POISSON((ROUNDUP($E17,0)+P$14),$E17,FALSE())+(1-$E17/(ROUNDUP($E17,0)+P$14))*POISSON((ROUNDUP($E17,0)+P$14)-1,$E17,TRUE()))*EXP(-((ROUNDUP($E17,0)+P$14)-$E17)*$C$11/$C$9)>=$C$10,(ROUNDUP($E17,0)+P$14),9999) -> 31 | Q17: =IF(1-POISSON((ROUNDUP($E17,0)+Q$14),$E17,FALSE())/(POISSON((ROUNDUP($E17,0)+Q$14),$E17,FALSE())+(1-$E17/(ROUNDUP($E17,0)+Q$14))*POISSON((ROUNDUP($E17,0)+Q$14)-1,$E17,TRUE()))*EXP(-((ROUNDUP($E17,0)+Q$14)-$E17)*$C$11/$C$9)>=$C$10,(ROUNDUP($E17,0)+Q$14),9999) -> 32 | ... AH17: =IF(1-POISSON((ROUNDUP($E17,0)+AH$14),$E17,FALSE())/(POISSON((ROUNDUP($E17,0)+AH$14),$E17,FALSE())+(1-$E17/(ROUNDUP($E17,0)+AH$14))*POISSON((ROUNDUP($E17,0)+AH$14)-1,$E17,TRUE()))*EXP(-((ROUNDUP($E17,0)+AH$14)-$E17)*$C$11/$C$9)>=$C$10,(ROUNDUP($E17,0)+AH$14),9999) -> 49
B18: 11:00-12:00 | C18: 0.07 | D18: =$C$8*C18 -> 1209.6 | E18: =D18*$C$9/3600 -> 25.2 | F18: =MIN(J18:AH18) -> 29 | G18: =1-POISSON(F18,E18,FALSE())/(POISSON(F18,E18,FALSE())+(1-E18/F18)*POISSON(F18-1,E18,TRUE()))*EXP(-(F18-E18)*$C$11/$C$9) -> 0.86797915 | H18: =E18/F18 -> 0.86896552 | J18: =IF(1-POISSON((ROUNDUP($E18,0)+J$14),$E18,FALSE())/(POISSON((ROUNDUP($E18,0)+J$14),$E18,FALSE())+(1-$E18/(ROUNDUP($E18,0)+J$14))*POISSON((ROUNDUP($E18,0)+J$14)-1,$E18,TRUE()))*EXP(-((ROUNDUP($E18,0)+J$14)-$E18)*$C$11/$C$9)>=$C$10,(ROUNDUP($E18,0)+J$14),9999) -> 9999 | K18: =IF(1-POISSON((ROUNDUP($E18,0)+K$14),$E18,FALSE())/(POISSON((ROUNDUP($E18,0)+K$14),$E18,FALSE())+(1-$E18/(ROUNDUP($E18,0)+K$14))*POISSON((ROUNDUP($E18,0)+K$14)-1,$E18,TRUE()))*EXP(-((ROUNDUP($E18,0)+K$14)-$E18)*$C$11/$C$9)>=$C$10,(ROUNDUP($E18,0)+K$14),9999) -> 9999 | L18: =IF(1-POISSON((ROUNDUP($E18,0)+L$14),$E18,FALSE())/(POISSON((ROUNDUP($E18,0)+L$14),$E18,FALSE())+(1-$E18/(ROUNDUP($E18,0)+L$14))*POISSON((ROUNDUP($E18,0)+L$14)-1,$E18,TRUE()))*EXP(-((ROUNDUP($E18,0)+L$14)-$E18)*$C$11/$C$9)>=$C$10,(ROUNDUP($E18,0)+L$14),9999) -> 29 | M18: =IF(1-POISSON((ROUNDUP($E18,0)+M$14),$E18,FALSE())/(POISSON((ROUNDUP($E18,0)+M$14),$E18,FALSE())+(1-$E18/(ROUNDUP($E18,0)+M$14))*POISSON((ROUNDUP($E18,0)+M$14)-1,$E18,TRUE()))*EXP(-((ROUNDUP($E18,0)+M$14)-$E18)*$C$11/$C$9)>=$C$10,(ROUNDUP($E18,0)+M$14),9999) -> 30 | N18: =IF(1-POISSON((ROUNDUP($E18,0)+N$14),$E18,FALSE())/(POISSON((ROUNDUP($E18,0)+N$14),$E18,FALSE())+(1-$E18/(ROUNDUP($E18,0)+N$14))*POISSON((ROUNDUP($E18,0)+N$14)-1,$E18,TRUE()))*EXP(-((ROUNDUP($E18,0)+N$14)-$E18)*$C$11/$C$9)>=$C$10,(ROUNDUP($E18,0)+N$14),9999) -> 31 | O18: =IF(1-POISSON((ROUNDUP($E18,0)+O$14),$E18,FALSE())/(POISSON((ROUNDUP($E18,0)+O$14),$E18,FALSE())+(1-$E18/(ROUNDUP($E18,0)+O$14))*POISSON((ROUNDUP($E18,0)+O$14)-1,$E18,TRUE()))*EXP(-((ROUNDUP($E18,0)+O$14)-$E18)*$C$11/$C$9)>=$C$10,(ROUNDUP($E18,0)+O$14),9999) -> 32 | P18: =IF(1-POISSON((ROUNDUP($E18,0)+P$14),$E18,FALSE())/(POISSON((ROUNDUP($E18,0)+P$14),$E18,FALSE())+(1-$E18/(ROUNDUP($E18,0)+P$14))*POISSON((ROUNDUP($E18,0)+P$14)-1,$E18,TRUE()))*EXP(-((ROUNDUP($E18,0)+P$14)-$E18)*$C$11/$C$9)>=$C$10,(ROUNDUP($E18,0)+P$14),9999) -> 33 | Q18: =IF(1-POISSON((ROUNDUP($E18,0)+Q$14),$E18,FALSE())/(POISSON((ROUNDUP($E18,0)+Q$14),$E18,FALSE())+(1-$E18/(ROUNDUP($E18,0)+Q$14))*POISSON((ROUNDUP($E18,0)+Q$14)-1,$E18,TRUE()))*EXP(-((ROUNDUP($E18,0)+Q$14)-$E18)*$C$11/$C$9)>=$C$10,(ROUNDUP($E18,0)+Q$14),9999) -> 34 | ... AH18: =IF(1-POISSON((ROUNDUP($E18,0)+AH$14),$E18,FALSE())/(POISSON((ROUNDUP($E18,0)+AH$14),$E18,FALSE())+(1-$E18/(ROUNDUP($E18,0)+AH$14))*POISSON((ROUNDUP($E18,0)+AH$14)-1,$E18,TRUE()))*EXP(-((ROUNDUP($E18,0)+AH$14)-$E18)*$C$11/$C$9)>=$C$10,(ROUNDUP($E18,0)+AH$14),9999) -> 51
B19: 12:00-13:00 | C19: 0.075 | D19: =$C$8*C19 -> 1296 | E19: =D19*$C$9/3600 -> 27 | F19: =MIN(J19:AH19) -> 31 | G19: =1-POISSON(F19,E19,FALSE())/(POISSON(F19,E19,FALSE())+(1-E19/F19)*POISSON(F19-1,E19,TRUE()))*EXP(-(F19-E19)*$C$11/$C$9) -> 0.87749647 | H19: =E19/F19 -> 0.87096774 | J19: =IF(1-POISSON((ROUNDUP($E19,0)+J$14),$E19,FALSE())/(POISSON((ROUNDUP($E19,0)+J$14),$E19,FALSE())+(1-$E19/(ROUNDUP($E19,0)+J$14))*POISSON((ROUNDUP($E19,0)+J$14)-1,$E19,TRUE()))*EXP(-((ROUNDUP($E19,0)+J$14)-$E19)*$C$11/$C$9)>=$C$10,(ROUNDUP($E19,0)+J$14),9999) -> 9999 | K19: =IF(1-POISSON((ROUNDUP($E19,0)+K$14),$E19,FALSE())/(POISSON((ROUNDUP($E19,0)+K$14),$E19,FALSE())+(1-$E19/(ROUNDUP($E19,0)+K$14))*POISSON((ROUNDUP($E19,0)+K$14)-1,$E19,TRUE()))*EXP(-((ROUNDUP($E19,0)+K$14)-$E19)*$C$11/$C$9)>=$C$10,(ROUNDUP($E19,0)+K$14),9999) -> 9999 | L19: =IF(1-POISSON((ROUNDUP($E19,0)+L$14),$E19,FALSE())/(POISSON((ROUNDUP($E19,0)+L$14),$E19,FALSE())+(1-$E19/(ROUNDUP($E19,0)+L$14))*POISSON((ROUNDUP($E19,0)+L$14)-1,$E19,TRUE()))*EXP(-((ROUNDUP($E19,0)+L$14)-$E19)*$C$11/$C$9)>=$C$10,(ROUNDUP($E19,0)+L$14),9999) -> 9999 | M19: =IF(1-POISSON((ROUNDUP($E19,0)+M$14),$E19,FALSE())/(POISSON((ROUNDUP($E19,0)+M$14),$E19,FALSE())+(1-$E19/(ROUNDUP($E19,0)+M$14))*POISSON((ROUNDUP($E19,0)+M$14)-1,$E19,TRUE()))*EXP(-((ROUNDUP($E19,0)+M$14)-$E19)*$C$11/$C$9)>=$C$10,(ROUNDUP($E19,0)+M$14),9999) -> 31 | N19: =IF(1-POISSON((ROUNDUP($E19,0)+N$14),$E19,FALSE())/(POISSON((ROUNDUP($E19,0)+N$14),$E19,FALSE())+(1-$E19/(ROUNDUP($E19,0)+N$14))*POISSON((ROUNDUP($E19,0)+N$14)-1,$E19,TRUE()))*EXP(-((ROUNDUP($E19,0)+N$14)-$E19)*$C$11/$C$9)>=$C$10,(ROUNDUP($E19,0)+N$14),9999) -> 32 | O19: =IF(1-POISSON((ROUNDUP($E19,0)+O$14),$E19,FALSE())/(POISSON((ROUNDUP($E19,0)+O$14),$E19,FALSE())+(1-$E19/(ROUNDUP($E19,0)+O$14))*POISSON((ROUNDUP($E19,0)+O$14)-1,$E19,TRUE()))*EXP(-((ROUNDUP($E19,0)+O$14)-$E19)*$C$11/$C$9)>=$C$10,(ROUNDUP($E19,0)+O$14),9999) -> 33 | P19: =IF(1-POISSON((ROUNDUP($E19,0)+P$14),$E19,FALSE())/(POISSON((ROUNDUP($E19,0)+P$14),$E19,FALSE())+(1-$E19/(ROUNDUP($E19,0)+P$14))*POISSON((ROUNDUP($E19,0)+P$14)-1,$E19,TRUE()))*EXP(-((ROUNDUP($E19,0)+P$14)-$E19)*$C$11/$C$9)>=$C$10,(ROUNDUP($E19,0)+P$14),9999) -> 34 | Q19: =IF(1-POISSON((ROUNDUP($E19,0)+Q$14),$E19,FALSE())/(POISSON((ROUNDUP($E19,0)+Q$14),$E19,FALSE())+(1-$E19/(ROUNDUP($E19,0)+Q$14))*POISSON((ROUNDUP($E19,0)+Q$14)-1,$E19,TRUE()))*EXP(-((ROUNDUP($E19,0)+Q$14)-$E19)*$C$11/$C$9)>=$C$10,(ROUNDUP($E19,0)+Q$14),9999) -> 35 | ... AH19: =IF(1-POISSON((ROUNDUP($E19,0)+AH$14),$E19,FALSE())/(POISSON((ROUNDUP($E19,0)+AH$14),$E19,FALSE())+(1-$E19/(ROUNDUP($E19,0)+AH$14))*POISSON((ROUNDUP($E19,0)+AH$14)-1,$E19,TRUE()))*EXP(-((ROUNDUP($E19,0)+AH$14)-$E19)*$C$11/$C$9)>=$C$10,(ROUNDUP($E19,0)+AH$14),9999) -> 52
B20: 13:00-14:00 | C20: 0.075 | D20: =$C$8*C20 -> 1296 | E20: =D20*$C$9/3600 -> 27 | F20: =MIN(J20:AH20) -> 31 | G20: =1-POISSON(F20,E20,FALSE())/(POISSON(F20,E20,FALSE())+(1-E20/F20)*POISSON(F20-1,E20,TRUE()))*EXP(-(F20-E20)*$C$11/$C$9) -> 0.87749647 | H20: =E20/F20 -> 0.87096774 | J20: =IF(1-POISSON((ROUNDUP($E20,0)+J$14),$E20,FALSE())/(POISSON((ROUNDUP($E20,0)+J$14),$E20,FALSE())+(1-$E20/(ROUNDUP($E20,0)+J$14))*POISSON((ROUNDUP($E20,0)+J$14)-1,$E20,TRUE()))*EXP(-((ROUNDUP($E20,0)+J$14)-$E20)*$C$11/$C$9)>=$C$10,(ROUNDUP($E20,0)+J$14),9999) -> 9999 | K20: =IF(1-POISSON((ROUNDUP($E20,0)+K$14),$E20,FALSE())/(POISSON((ROUNDUP($E20,0)+K$14),$E20,FALSE())+(1-$E20/(ROUNDUP($E20,0)+K$14))*POISSON((ROUNDUP($E20,0)+K$14)-1,$E20,TRUE()))*EXP(-((ROUNDUP($E20,0)+K$14)-$E20)*$C$11/$C$9)>=$C$10,(ROUNDUP($E20,0)+K$14),9999) -> 9999 | L20: =IF(1-POISSON((ROUNDUP($E20,0)+L$14),$E20,FALSE())/(POISSON((ROUNDUP($E20,0)+L$14),$E20,FALSE())+(1-$E20/(ROUNDUP($E20,0)+L$14))*POISSON((ROUNDUP($E20,0)+L$14)-1,$E20,TRUE()))*EXP(-((ROUNDUP($E20,0)+L$14)-$E20)*$C$11/$C$9)>=$C$10,(ROUNDUP($E20,0)+L$14),9999) -> 9999 | M20: =IF(1-POISSON((ROUNDUP($E20,0)+M$14),$E20,FALSE())/(POISSON((ROUNDUP($E20,0)+M$14),$E20,FALSE())+(1-$E20/(ROUNDUP($E20,0)+M$14))*POISSON((ROUNDUP($E20,0)+M$14)-1,$E20,TRUE()))*EXP(-((ROUNDUP($E20,0)+M$14)-$E20)*$C$11/$C$9)>=$C$10,(ROUNDUP($E20,0)+M$14),9999) -> 31 | N20: =IF(1-POISSON((ROUNDUP($E20,0)+N$14),$E20,FALSE())/(POISSON((ROUNDUP($E20,0)+N$14),$E20,FALSE())+(1-$E20/(ROUNDUP($E20,0)+N$14))*POISSON((ROUNDUP($E20,0)+N$14)-1,$E20,TRUE()))*EXP(-((ROUNDUP($E20,0)+N$14)-$E20)*$C$11/$C$9)>=$C$10,(ROUNDUP($E20,0)+N$14),9999) -> 32 | O20: =IF(1-POISSON((ROUNDUP($E20,0)+O$14),$E20,FALSE())/(POISSON((ROUNDUP($E20,0)+O$14),$E20,FALSE())+(1-$E20/(ROUNDUP($E20,0)+O$14))*POISSON((ROUNDUP($E20,0)+O$14)-1,$E20,TRUE()))*EXP(-((ROUNDUP($E20,0)+O$14)-$E20)*$C$11/$C$9)>=$C$10,(ROUNDUP($E20,0)+O$14),9999) -> 33 | P20: =IF(1-POISSON((ROUNDUP($E20,0)+P$14),$E20,FALSE())/(POISSON((ROUNDUP($E20,0)+P$14),$E20,FALSE())+(1-$E20/(ROUNDUP($E20,0)+P$14))*POISSON((ROUNDUP($E20,0)+P$14)-1,$E20,TRUE()))*EXP(-((ROUNDUP($E20,0)+P$14)-$E20)*$C$11/$C$9)>=$C$10,(ROUNDUP($E20,0)+P$14),9999) -> 34 | Q20: =IF(1-POISSON((ROUNDUP($E20,0)+Q$14),$E20,FALSE())/(POISSON((ROUNDUP($E20,0)+Q$14),$E20,FALSE())+(1-$E20/(ROUNDUP($E20,0)+Q$14))*POISSON((ROUNDUP($E20,0)+Q$14)-1,$E20,TRUE()))*EXP(-((ROUNDUP($E20,0)+Q$14)-$E20)*$C$11/$C$9)>=$C$10,(ROUNDUP($E20,0)+Q$14),9999) -> 35 | ... AH20: =IF(1-POISSON((ROUNDUP($E20,0)+AH$14),$E20,FALSE())/(POISSON((ROUNDUP($E20,0)+AH$14),$E20,FALSE())+(1-$E20/(ROUNDUP($E20,0)+AH$14))*POISSON((ROUNDUP($E20,0)+AH$14)-1,$E20,TRUE()))*EXP(-((ROUNDUP($E20,0)+AH$14)-$E20)*$C$11/$C$9)>=$C$10,(ROUNDUP($E20,0)+AH$14),9999) -> 52
B21: 14:00-15:00 | C21: 0.065 | D21: =$C$8*C21 -> 1123.2 | E21: =D21*$C$9/3600 -> 23.4 | F21: =MIN(J21:AH21) -> 27 | G21: =1-POISSON(F21,E21,FALSE())/(POISSON(F21,E21,FALSE())+(1-E21/F21)*POISSON(F21-1,E21,TRUE()))*EXP(-(F21-E21)*$C$11/$C$9) -> 0.85772559 | H21: =E21/F21 -> 0.86666667 | J21: =IF(1-POISSON((ROUNDUP($E21,0)+J$14),$E21,FALSE())/(POISSON((ROUNDUP($E21,0)+J$14),$E21,FALSE())+(1-$E21/(ROUNDUP($E21,0)+J$14))*POISSON((ROUNDUP($E21,0)+J$14)-1,$E21,TRUE()))*EXP(-((ROUNDUP($E21,0)+J$14)-$E21)*$C$11/$C$9)>=$C$10,(ROUNDUP($E21,0)+J$14),9999) -> 9999 | K21: =IF(1-POISSON((ROUNDUP($E21,0)+K$14),$E21,FALSE())/(POISSON((ROUNDUP($E21,0)+K$14),$E21,FALSE())+(1-$E21/(ROUNDUP($E21,0)+K$14))*POISSON((ROUNDUP($E21,0)+K$14)-1,$E21,TRUE()))*EXP(-((ROUNDUP($E21,0)+K$14)-$E21)*$C$11/$C$9)>=$C$10,(ROUNDUP($E21,0)+K$14),9999) -> 9999 | L21: =IF(1-POISSON((ROUNDUP($E21,0)+L$14),$E21,FALSE())/(POISSON((ROUNDUP($E21,0)+L$14),$E21,FALSE())+(1-$E21/(ROUNDUP($E21,0)+L$14))*POISSON((ROUNDUP($E21,0)+L$14)-1,$E21,TRUE()))*EXP(-((ROUNDUP($E21,0)+L$14)-$E21)*$C$11/$C$9)>=$C$10,(ROUNDUP($E21,0)+L$14),9999) -> 27 | M21: =IF(1-POISSON((ROUNDUP($E21,0)+M$14),$E21,FALSE())/(POISSON((ROUNDUP($E21,0)+M$14),$E21,FALSE())+(1-$E21/(ROUNDUP($E21,0)+M$14))*POISSON((ROUNDUP($E21,0)+M$14)-1,$E21,TRUE()))*EXP(-((ROUNDUP($E21,0)+M$14)-$E21)*$C$11/$C$9)>=$C$10,(ROUNDUP($E21,0)+M$14),9999) -> 28 | N21: =IF(1-POISSON((ROUNDUP($E21,0)+N$14),$E21,FALSE())/(POISSON((ROUNDUP($E21,0)+N$14),$E21,FALSE())+(1-$E21/(ROUNDUP($E21,0)+N$14))*POISSON((ROUNDUP($E21,0)+N$14)-1,$E21,TRUE()))*EXP(-((ROUNDUP($E21,0)+N$14)-$E21)*$C$11/$C$9)>=$C$10,(ROUNDUP($E21,0)+N$14),9999) -> 29 | O21: =IF(1-POISSON((ROUNDUP($E21,0)+O$14),$E21,FALSE())/(POISSON((ROUNDUP($E21,0)+O$14),$E21,FALSE())+(1-$E21/(ROUNDUP($E21,0)+O$14))*POISSON((ROUNDUP($E21,0)+O$14)-1,$E21,TRUE()))*EXP(-((ROUNDUP($E21,0)+O$14)-$E21)*$C$11/$C$9)>=$C$10,(ROUNDUP($E21,0)+O$14),9999) -> 30 | P21: =IF(1-POISSON((ROUNDUP($E21,0)+P$14),$E21,FALSE())/(POISSON((ROUNDUP($E21,0)+P$14),$E21,FALSE())+(1-$E21/(ROUNDUP($E21,0)+P$14))*POISSON((ROUNDUP($E21,0)+P$14)-1,$E21,TRUE()))*EXP(-((ROUNDUP($E21,0)+P$14)-$E21)*$C$11/$C$9)>=$C$10,(ROUNDUP($E21,0)+P$14),9999) -> 31 | Q21: =IF(1-POISSON((ROUNDUP($E21,0)+Q$14),$E21,FALSE())/(POISSON((ROUNDUP($E21,0)+Q$14),$E21,FALSE())+(1-$E21/(ROUNDUP($E21,0)+Q$14))*POISSON((ROUNDUP($E21,0)+Q$14)-1,$E21,TRUE()))*EXP(-((ROUNDUP($E21,0)+Q$14)-$E21)*$C$11/$C$9)>=$C$10,(ROUNDUP($E21,0)+Q$14),9999) -> 32 | ... AH21: =IF(1-POISSON((ROUNDUP($E21,0)+AH$14),$E21,FALSE())/(POISSON((ROUNDUP($E21,0)+AH$14),$E21,FALSE())+(1-$E21/(ROUNDUP($E21,0)+AH$14))*POISSON((ROUNDUP($E21,0)+AH$14)-1,$E21,TRUE()))*EXP(-((ROUNDUP($E21,0)+AH$14)-$E21)*$C$11/$C$9)>=$C$10,(ROUNDUP($E21,0)+AH$14),9999) -> 49
B22: 15:00-16:00 | C22: 0.06 | D22: =$C$8*C22 -> 1036.8 | E22: =D22*$C$9/3600 -> 21.6 | F22: =MIN(J22:AH22) -> 25 | G22: =1-POISSON(F22,E22,FALSE())/(POISSON(F22,E22,FALSE())+(1-E22/F22)*POISSON(F22-1,E22,TRUE()))*EXP(-(F22-E22)*$C$11/$C$9) -> 0.84669057 | H22: =E22/F22 -> 0.864 | J22: =IF(1-POISSON((ROUNDUP($E22,0)+J$14),$E22,FALSE())/(POISSON((ROUNDUP($E22,0)+J$14),$E22,FALSE())+(1-$E22/(ROUNDUP($E22,0)+J$14))*POISSON((ROUNDUP($E22,0)+J$14)-1,$E22,TRUE()))*EXP(-((ROUNDUP($E22,0)+J$14)-$E22)*$C$11/$C$9)>=$C$10,(ROUNDUP($E22,0)+J$14),9999) -> 9999 | K22: =IF(1-POISSON((ROUNDUP($E22,0)+K$14),$E22,FALSE())/(POISSON((ROUNDUP($E22,0)+K$14),$E22,FALSE())+(1-$E22/(ROUNDUP($E22,0)+K$14))*POISSON((ROUNDUP($E22,0)+K$14)-1,$E22,TRUE()))*EXP(-((ROUNDUP($E22,0)+K$14)-$E22)*$C$11/$C$9)>=$C$10,(ROUNDUP($E22,0)+K$14),9999) -> 9999 | L22: =IF(1-POISSON((ROUNDUP($E22,0)+L$14),$E22,FALSE())/(POISSON((ROUNDUP($E22,0)+L$14),$E22,FALSE())+(1-$E22/(ROUNDUP($E22,0)+L$14))*POISSON((ROUNDUP($E22,0)+L$14)-1,$E22,TRUE()))*EXP(-((ROUNDUP($E22,0)+L$14)-$E22)*$C$11/$C$9)>=$C$10,(ROUNDUP($E22,0)+L$14),9999) -> 25 | M22: =IF(1-POISSON((ROUNDUP($E22,0)+M$14),$E22,FALSE())/(POISSON((ROUNDUP($E22,0)+M$14),$E22,FALSE())+(1-$E22/(ROUNDUP($E22,0)+M$14))*POISSON((ROUNDUP($E22,0)+M$14)-1,$E22,TRUE()))*EXP(-((ROUNDUP($E22,0)+M$14)-$E22)*$C$11/$C$9)>=$C$10,(ROUNDUP($E22,0)+M$14),9999) -> 26 | N22: =IF(1-POISSON((ROUNDUP($E22,0)+N$14),$E22,FALSE())/(POISSON((ROUNDUP($E22,0)+N$14),$E22,FALSE())+(1-$E22/(ROUNDUP($E22,0)+N$14))*POISSON((ROUNDUP($E22,0)+N$14)-1,$E22,TRUE()))*EXP(-((ROUNDUP($E22,0)+N$14)-$E22)*$C$11/$C$9)>=$C$10,(ROUNDUP($E22,0)+N$14),9999) -> 27 | O22: =IF(1-POISSON((ROUNDUP($E22,0)+O$14),$E22,FALSE())/(POISSON((ROUNDUP($E22,0)+O$14),$E22,FALSE())+(1-$E22/(ROUNDUP($E22,0)+O$14))*POISSON((ROUNDUP($E22,0)+O$14)-1,$E22,TRUE()))*EXP(-((ROUNDUP($E22,0)+O$14)-$E22)*$C$11/$C$9)>=$C$10,(ROUNDUP($E22,0)+O$14),9999) -> 28 | P22: =IF(1-POISSON((ROUNDUP($E22,0)+P$14),$E22,FALSE())/(POISSON((ROUNDUP($E22,0)+P$14),$E22,FALSE())+(1-$E22/(ROUNDUP($E22,0)+P$14))*POISSON((ROUNDUP($E22,0)+P$14)-1,$E22,TRUE()))*EXP(-((ROUNDUP($E22,0)+P$14)-$E22)*$C$11/$C$9)>=$C$10,(ROUNDUP($E22,0)+P$14),9999) -> 29 | Q22: =IF(1-POISSON((ROUNDUP($E22,0)+Q$14),$E22,FALSE())/(POISSON((ROUNDUP($E22,0)+Q$14),$E22,FALSE())+(1-$E22/(ROUNDUP($E22,0)+Q$14))*POISSON((ROUNDUP($E22,0)+Q$14)-1,$E22,TRUE()))*EXP(-((ROUNDUP($E22,0)+Q$14)-$E22)*$C$11/$C$9)>=$C$10,(ROUNDUP($E22,0)+Q$14),9999) -> 30 | ... AH22: =IF(1-POISSON((ROUNDUP($E22,0)+AH$14),$E22,FALSE())/(POISSON((ROUNDUP($E22,0)+AH$14),$E22,FALSE())+(1-$E22/(ROUNDUP($E22,0)+AH$14))*POISSON((ROUNDUP($E22,0)+AH$14)-1,$E22,TRUE()))*EXP(-((ROUNDUP($E22,0)+AH$14)-$E22)*$C$11/$C$9)>=$C$10,(ROUNDUP($E22,0)+AH$14),9999) -> 47
B23: 16:00-17:00 | C23: 0.06 | D23: =$C$8*C23 -> 1036.8 | E23: =D23*$C$9/3600 -> 21.6 | F23: =MIN(J23:AH23) -> 25 | G23: =1-POISSON(F23,E23,FALSE())/(POISSON(F23,E23,FALSE())+(1-E23/F23)*POISSON(F23-1,E23,TRUE()))*EXP(-(F23-E23)*$C$11/$C$9) -> 0.84669057 | H23: =E23/F23 -> 0.864 | J23: =IF(1-POISSON((ROUNDUP($E23,0)+J$14),$E23,FALSE())/(POISSON((ROUNDUP($E23,0)+J$14),$E23,FALSE())+(1-$E23/(ROUNDUP($E23,0)+J$14))*POISSON((ROUNDUP($E23,0)+J$14)-1,$E23,TRUE()))*EXP(-((ROUNDUP($E23,0)+J$14)-$E23)*$C$11/$C$9)>=$C$10,(ROUNDUP($E23,0)+J$14),9999) -> 9999 | K23: =IF(1-POISSON((ROUNDUP($E23,0)+K$14),$E23,FALSE())/(POISSON((ROUNDUP($E23,0)+K$14),$E23,FALSE())+(1-$E23/(ROUNDUP($E23,0)+K$14))*POISSON((ROUNDUP($E23,0)+K$14)-1,$E23,TRUE()))*EXP(-((ROUNDUP($E23,0)+K$14)-$E23)*$C$11/$C$9)>=$C$10,(ROUNDUP($E23,0)+K$14),9999) -> 9999 | L23: =IF(1-POISSON((ROUNDUP($E23,0)+L$14),$E23,FALSE())/(POISSON((ROUNDUP($E23,0)+L$14),$E23,FALSE())+(1-$E23/(ROUNDUP($E23,0)+L$14))*POISSON((ROUNDUP($E23,0)+L$14)-1,$E23,TRUE()))*EXP(-((ROUNDUP($E23,0)+L$14)-$E23)*$C$11/$C$9)>=$C$10,(ROUNDUP($E23,0)+L$14),9999) -> 25 | M23: =IF(1-POISSON((ROUNDUP($E23,0)+M$14),$E23,FALSE())/(POISSON((ROUNDUP($E23,0)+M$14),$E23,FALSE())+(1-$E23/(ROUNDUP($E23,0)+M$14))*POISSON((ROUNDUP($E23,0)+M$14)-1,$E23,TRUE()))*EXP(-((ROUNDUP($E23,0)+M$14)-$E23)*$C$11/$C$9)>=$C$10,(ROUNDUP($E23,0)+M$14),9999) -> 26 | N23: =IF(1-POISSON((ROUNDUP($E23,0)+N$14),$E23,FALSE())/(POISSON((ROUNDUP($E23,0)+N$14),$E23,FALSE())+(1-$E23/(ROUNDUP($E23,0)+N$14))*POISSON((ROUNDUP($E23,0)+N$14)-1,$E23,TRUE()))*EXP(-((ROUNDUP($E23,0)+N$14)-$E23)*$C$11/$C$9)>=$C$10,(ROUNDUP($E23,0)+N$14),9999) -> 27 | O23: =IF(1-POISSON((ROUNDUP($E23,0)+O$14),$E23,FALSE())/(POISSON((ROUNDUP($E23,0)+O$14),$E23,FALSE())+(1-$E23/(ROUNDUP($E23,0)+O$14))*POISSON((ROUNDUP($E23,0)+O$14)-1,$E23,TRUE()))*EXP(-((ROUNDUP($E23,0)+O$14)-$E23)*$C$11/$C$9)>=$C$10,(ROUNDUP($E23,0)+O$14),9999) -> 28 | P23: =IF(1-POISSON((ROUNDUP($E23,0)+P$14),$E23,FALSE())/(POISSON((ROUNDUP($E23,0)+P$14),$E23,FALSE())+(1-$E23/(ROUNDUP($E23,0)+P$14))*POISSON((ROUNDUP($E23,0)+P$14)-1,$E23,TRUE()))*EXP(-((ROUNDUP($E23,0)+P$14)-$E23)*$C$11/$C$9)>=$C$10,(ROUNDUP($E23,0)+P$14),9999) -> 29 | Q23: =IF(1-POISSON((ROUNDUP($E23,0)+Q$14),$E23,FALSE())/(POISSON((ROUNDUP($E23,0)+Q$14),$E23,FALSE())+(1-$E23/(ROUNDUP($E23,0)+Q$14))*POISSON((ROUNDUP($E23,0)+Q$14)-1,$E23,TRUE()))*EXP(-((ROUNDUP($E23,0)+Q$14)-$E23)*$C$11/$C$9)>=$C$10,(ROUNDUP($E23,0)+Q$14),9999) -> 30 | ... AH23: =IF(1-POISSON((ROUNDUP($E23,0)+AH$14),$E23,FALSE())/(POISSON((ROUNDUP($E23,0)+AH$14),$E23,FALSE())+(1-$E23/(ROUNDUP($E23,0)+AH$14))*POISSON((ROUNDUP($E23,0)+AH$14)-1,$E23,TRUE()))*EXP(-((ROUNDUP($E23,0)+AH$14)-$E23)*$C$11/$C$9)>=$C$10,(ROUNDUP($E23,0)+AH$14),9999) -> 47
